Workbook
Name NativeTimeline_Attendance_Date: #N/A
Name Slicer_Attendance_Status: #N/A
Name Slicer_Correct_Shift: #N/A
Name Slicer_Department: #N/A

Sheet row-data
A1: Employee_ID | B1: Attendance_Date | C1: Department | D1: Shift | E1: Check_In | F1: Check_Out | G1: Attendance_Status
A2: EMP073 | B2: 45939 | C2: Administration | D2: Morning | E2: 14:08 | F2: 22:18 | G2: Present
A3: EMP013 | B3: 46103 | C3: HR | D3: Morning | E3: 14:03 | F3: 22:12 | G3: Present
A4: EMP049 | B4: 45778 | C4: Administration | D4: Evening | E4: 08:41 | F4: 17:10 | G4: Late
A5: EMP080 | B5: 46026 | C5: IT | D5: Morning | F5: 17:05 | G5: Present
A6: EMP037 | B6: 45932 | C6: Operations | D6: Morning | E6: 08:38 | F6: 17:21 | G6: Late
A7: EMP016 | B7: 45696 | C7: Finance | E7: 08:04 | F7: 17:29 | G7: Remote
A8: EMP027 | B8: 45692 | C8: Sales | D8: MORNING | E8: 08:10 | F8: 17:23 | G8: Late
A9: EMP033 | B9: 45748 | C9: Administration | D9: Evening | E9: - | F9: - | G9: Absent
A10: EMP034 | B10: 46210 | C10: Operations | D10: Evening | E10: 08:09 | F10: 17:07 | G10: Present
A11: EMP031 | B11: 45921 | C11: Operations | D11: Evening | F11: - | G11: Absent
A12: EMP053 | B12: 45774 | C12: IT | D12: Morning | E12: 08:01 | F12: 17:25 | G12: Present
A13: EMP076 | B13: 46168 | C13: Finance | D13: Evening | E13: 08:08 | F13: 17:25 | G13: Present
A14: EMP040 | B14: 45671 | C14: Operations | D14: Morning | E14: 08:05 | F14: 17:05 | G14: Present
A15: EMP062 | B15: 46167 | C15: Sales | D15: Morning | E15: 08:00 | F15: 17:18 | G15: Present
A16: EMP047 | B16: 45986 | C16: Finance | D16: Morning | E16: 08:04 | G16: Present
A17: EMP017 | B17: 45783 | C17: IT | D17: Morning | E17: 08:06 | F17: 17:27 | G17: Present
A18: EMP018 | B18: 45933 | C18: Administration | D18: Morning | E18: 08:09 | F18: 17:19 | G18: Present
A19: EMP046 | B19: 46125 | C19: Administration | D19: Morning | E19: 08:15 | F19: 17:15 | G19: Late
A20: EMP042 | B20: 46095 | C20: Administration | D20: Morning | E20: 08:03 | F20: 17:13 | G20: Present
A21: EMP012 | B21: 45787 | C21: Sales | D21: Morning | E21: 08:00 | F21: 17:03
A22: EMP014 | B22: 46012 | C22: Sales | D22: Evening | E22: 08:04 | F22: 17:19 | G22: Present
A23: EMP064 | B23: 45927 | C23: Finance | D23: Evening | E23: 08:41 | F23: 17:06 | G23: Late
A24: EMP011 | B24: 45924 | C24: Sales | D24: Evening | E24: 14:01 | F24: 22:24 | G24: Present
A25: EMP008 | C25: Sales | D25: Morning | E25: 09:52 | F25: 17:06 | G25: Late
A26: EMP075 | B26: 46136 | C26: Sales | D26: Morning | E26: - | F26: - | G26: Absent
A27: EMP043 | B27: 45697 | C27: Sales | D27: Morning | E27: 08:00 | F27: 17:29 | G27: Present
A28: EMP040 | B28: 46014 | C28: HR | D28: Evening | F28: 17:10 | G28: Present
A29: EMP013 | B29: 46228 | C29: HR | D29: Morning | E29: 08:08 | G29: Present
A30: EMP035 | B30: 45955 | C30: Administration | D30: Evening | E30: 08:00 | F30: 17:03 | G30: Present
A31: EMP058 | B31: 46130 | C31: Operations | D31: Morning | E31: 14:07 | F31: 22:12 | G31: Remote
A32: EMP044 | B32: 46111 | C32: Finance | E32: 08:03 | F32: 17:10 | G32: Present
A33: EMP066 | C33: Finance | D33: Morning | E33: 08:04 | F33: 17:13 | G33: Present
A34: EMP061 | B34: 46167 | C34: Operations | D34: Morning | E34: 08:00 | F34: 17:11 | G34: Present
A35: EMP072 | B35: 45939 | C35: HR | D35: Morning | E35: 14:08 | F35: 22:01 | G35: Present
A36: EMP074 | B36: 45869 | C36: Finance | D36: Morning | E36: 14:27 | F36: 22:26 | G36: Late
A37: EMP026 | B37: 46026 | C37: Administration | D37: Evening | E37: 08:06 | F37: 17:07 | G37: Present
A38: EMP020 | B38: 45918 | C38: Administration | D38: Evening | E38: 08:04 | F38: 17:02 | G38: Remote
A39: EMP019 | B39: 45876 | C39: N/A | D39: Morning | E39: 14:05 | F39: 22:22
A40: EMP049 | B40: 45762 | C40: Administration | D40: Morning | E40: 14:00 | F40: 22:11 | G40: Present
...

Sheet cleaned-data
A1: Employee_ID | B1: Attendance_Date | C1: Department | D1: Shift | E1: Check_In | F1: Check_Out | G1: Attendance_Status | H1: Correct Shift
A2: EMP073 | B2: 45939 | C2: Administration | D2: Morning | E2: 14:08 | F2: 22:18 | G2: Present | H2: =IFERROR(IF(TIMEVALUE(E2)<TIME(12,0,0),"Morning","Evening"),D2) -> Evening
A3: EMP013 | B3: 46103 | C3: HR | D3: Morning | E3: 14:03 | F3: 22:12 | G3: Present | H3: =IFERROR(IF(TIMEVALUE(E3)<TIME(12,0,0),"Morning","Evening"),D3) -> Evening
A4: EMP049 | B4: 45778 | C4: Administration | D4: Evening | E4: 08:41 | F4: 17:10 | G4: Late | H4: =IFERROR(IF(TIMEVALUE(E4)<TIME(12,0,0),"Morning","Evening"),D4) -> Morning
A5: EMP080 | B5: 46026 | C5: IT | D5: Morning | E5: 0.33958333 | F5: 17:05 | G5: Present | H5: =IFERROR(IF(TIMEVALUE(E5)<TIME(12,0,0),"Morning","Evening"),D5) -> Morning | S5: Column | T5: Count | W5: Column | X5: Missing | Y5: Best Method | Z5: Reason
A6: EMP037 | B6: 45932 | C6: Operations | D6: Morning | E6: 08:38 | F6: 17:21 | G6: Late | H6: =IFERROR(IF(TIMEVALUE(E6)<TIME(12,0,0),"Morning","Evening"),D6) -> Morning | S6: origin data | T6: 300 | W6: Employee_ID | X6: 15 | Y6: Delete rows | Z6: ID is a unique identifier and cannot be reliably estimated.
A7: EMP016 | B7: 45696 | C7: Finance | D7: Morning | E7: 08:04 | F7: 17:29 | G7: Remote | H7: =IFERROR(IF(TIMEVALUE(E7)<TIME(12,0,0),"Morning","Evening"),D7) -> Morning | S7: duplicate | T7: 7 | W7: Attendance_Date | X7: 17 | Y7: Delete rows | Z7: The correct attendance date cannot be reliably determined.
A8: EMP027 | B8: 45692 | C8: Sales | D8: Morning | E8: 08:10 | F8: 17:23 | G8: Late | H8: =IFERROR(IF(TIMEVALUE(E8)<TIME(12,0,0),"Morning","Evening"),D8) -> Morning | S8: after removing duplicate | T8: 293 | W8: Department | X8: 18 | Y8: Mode | Z8: Department is categorical, so the most frequent category can be used.
A9: EMP033 | B9: 45748 | C9: Administration | D9: Evening | E9: - | F9: - | G9: Absent | H9: =IFERROR(IF(TIMEVALUE(E9)<TIME(12,0,0),"Morning","Evening"),D9) -> Evening | S9: after removing blank-ids | T9: 278 | W9: Shift | X9: 18 | Y9: Check_In-based / Mode | Z9: If Check_In is available, it can indicate the appropriate shift; otherwise, use the mode.
A10: EMP034 | B10: 46210 | C10: Operations | D10: Evening | E10: 08:09 | F10: 17:07 | G10: Present | H10: =IFERROR(IF(TIMEVALUE(E10)<TIME(12,0,0),"Morning","Evening"),D10) -> Morning | S10: after removing-att-missing-date | T10: 261 | W10: Check_In | X10: 41 | Y10: Median | Z10: Time is numeric and the median is less affected by extreme values (outliers).
A11: EMP031 | B11: 45921 | C11: Operations | D11: Evening | F11: - | G11: Absent | H11: =IFERROR(IF(TIMEVALUE(E11)<TIME(12,0,0),"Morning","Evening"),D11) -> Evening | W11: Check_Out | X11: 38 | Y11: Median | Z11: Time is numeric and median is appropriate for handling missing time values.
A12: EMP053 | B12: 45774 | C12: IT | D12: Morning | E12: 08:01 | F12: 17:25 | G12: Present | H12: =IFERROR(IF(TIMEVALUE(E12)<TIME(12,0,0),"Morning","Evening"),D12) -> Morning | S12: departments | T12: count | W12: Attendance_Status | X12: 16 | Y12: Logical rule / Mode | Z12: It can be inferred from Check_In and Check_Out; if it cannot be determined, use the mode.
A13: EMP076 | B13: 46168 | C13: Finance | D13: Evening | E13: 08:08 | F13: 17:25 | G13: Present | H13: =IFERROR(IF(TIMEVALUE(E13)<TIME(12,0,0),"Morning","Evening"),D13) -> Morning | S13: IT | T13: =COUNTIF(C2:C262,"IT") -> 76
A14: EMP040 | B14: 45671 | C14: Operations | D14: Morning | E14: 08:05 | F14: 17:05 | G14: Present | H14: =IFERROR(IF(TIMEVALUE(E14)<TIME(12,0,0),"Morning","Evening"),D14) -> Morning | S14: Administration | T14: =COUNTIF(C2:C262,"Administration") -> 30
A15: EMP062 | B15: 46167 | C15: Sales | D15: Morning | E15: 08:00 | F15: 17:18 | G15: Present | H15: =IFERROR(IF(TIMEVALUE(E15)<TIME(12,0,0),"Morning","Evening"),D15) -> Morning | S15: HR | T15: =COUNTIF(C2:C262,"HR") -> 20
A16: EMP047 | B16: 45986 | C16: Finance | D16: Morning | E16: 08:04 | F16: 0.71319444 | G16: Present | H16: =IFERROR(IF(TIMEVALUE(E16)<TIME(12,0,0),"Morning","Evening"),D16) -> Morning | S16: Sales | T16: =COUNTIF(C2:C262,"Sales") -> 39
A17: EMP017 | B17: 45783 | C17: IT | D17: Morning | E17: 08:06 | F17: 17:27 | G17: Present | H17: =IFERROR(IF(TIMEVALUE(E17)<TIME(12,0,0),"Morning","Evening"),D17) -> Morning | S17: Finance | T17: =COUNTIF(C2:C262,"Finance") -> 45
A18: EMP018 | B18: 45933 | C18: Administration | D18: Morning | E18: 08:09 | F18: 17:19 | G18: Present | H18: =IFERROR(IF(TIMEVALUE(E18)<TIME(12,0,0),"Morning","Evening"),D18) -> Morning | S18: Operations | T18: =COUNTIF(C2:C262,"Operations") -> 51
A19: EMP046 | B19: 46125 | C19: Administration | D19: Morning | E19: 08:15 | F19: 17:15 | G19: Late | H19: =IFERROR(IF(TIMEVALUE(E19)<TIME(12,0,0),"Morning","Evening"),D19) -> Morning
A20: EMP042 | B20: 46095 | C20: Administration | D20: Morning | E20: 08:03 | F20: 17:13 | G20: Present | H20: =IFERROR(IF(TIMEVALUE(E20)<TIME(12,0,0),"Morning","Evening"),D20) -> Morning
A21: EMP012 | B21: 45787 | C21: Sales | D21: Morning | E21: 08:00 | F21: 17:03 | G21: Present | H21: =IFERROR(IF(TIMEVALUE(E21)<TIME(12,0,0),"Morning","Evening"),D21) -> Morning
A22: EMP014 | B22: 46012 | C22: Sales | D22: Evening | E22: 08:04 | F22: 17:19 | G22: Present | H22: =IFERROR(IF(TIMEVALUE(E22)<TIME(12,0,0),"Morning","Evening"),D22) -> Morning | S22: Column1 | T22: Column2
A23: EMP064 | B23: 45927 | C23: Finance | D23: Evening | E23: 08:41 | F23: 17:06 | G23: Late | H23: =IFERROR(IF(TIMEVALUE(E23)<TIME(12,0,0),"Morning","Evening"),D23) -> Morning | S23: check in Morning median | T23: 0.58680556
A24: EMP011 | B24: 45924 | C24: Sales | D24: Evening | E24: 14:01 | F24: 22:24 | G24: Present | H24: =IFERROR(IF(TIMEVALUE(E24)<TIME(12,0,0),"Morning","Evening"),D24) -> Evening | S24: check in Evening median | T24: 0.33958333
A25: EMP075 | B25: 46136 | C25: Sales | D25: Morning | E25: - | F25: - | G25: Absent | H25: =IFERROR(IF(TIMEVALUE(E25)<TIME(12,0,0),"Morning","Evening"),D25) -> Morning
A26: EMP043 | B26: 45697 | C26: Sales | D26: Morning | E26: 08:00 | F26: 17:29 | G26: Present | H26: =IFERROR(IF(TIMEVALUE(E26)<TIME(12,0,0),"Morning","Evening"),D26) -> Morning
A27: EMP040 | B27: 46014 | C27: HR | D27: Evening | E27: 0.58680556 | F27: 17:10 | G27: Present | H27: =IFERROR(IF(TIMEVALUE(E27)<TIME(12,0,0),"Morning","Evening"),D27) -> Evening
A28: EMP013 | B28: 46228 | C28: HR | D28: Morning | E28: 08:08 | F28: 0.71319444 | G28: Present | H28: =IFERROR(IF(TIMEVALUE(E28)<TIME(12,0,0),"Morning","Evening"),D28) -> Morning
A29: EMP035 | B29: 45955 | C29: Administration | D29: Evening | E29: 08:00 | F29: 17:03 | G29: Present | H29: =IFERROR(IF(TIMEVALUE(E29)<TIME(12,0,0),"Morning","Evening"),D29) -> Morning
A30: EMP058 | B30: 46130 | C30: Operations | D30: Morning | E30: 14:07 | F30: 22:12 | G30: Remote | H30: =IFERROR(IF(TIMEVALUE(E30)<TIME(12,0,0),"Morning","Evening"),D30) -> Evening
A31: EMP044 | B31: 46111 | C31: Finance | D31: Morning | E31: 08:03 | F31: 17:10 | G31: Present | H31: =IFERROR(IF(TIMEVALUE(E31)<TIME(12,0,0),"Morning","Evening"),D31) -> Morning
A32: EMP061 | B32: 46167 | C32: Operations | D32: Morning | E32: 08:00 | F32: 17:11 | G32: Present | H32: =IFERROR(IF(TIMEVALUE(E32)<TIME(12,0,0),"Morning","Evening"),D32) -> Morning
A33: EMP072 | B33: 45939 | C33: HR | D33: Morning | E33: 14:08 | F33: 22:01 | G33: Present | H33: =IFERROR(IF(TIMEVALUE(E33)<TIME(12,0,0),"Morning","Evening"),D33) -> Evening
A34: EMP074 | B34: 45869 | C34: Finance | D34: Morning | E34: 14:27 | F34: 22:26 | G34: Late | H34: =IFERROR(IF(TIMEVALUE(E34)<TIME(12,0,0),"Morning","Evening"),D34) -> Evening
A35: EMP026 | B35: 46026 | C35: Administration | D35: Evening | E35: 08:06 | F35: 17:07 | G35: Present | H35: =IFERROR(IF(TIMEVALUE(E35)<TIME(12,0,0),"Morning","Evening"),D35) -> Morning | S35: Morning Check_Out Median | T35: 17:07
A36: EMP020 | B36: 45918 | C36: Administration | D36: Evening | E36: 08:04 | F36: 17:02 | G36: Remote | H36: =IFERROR(IF(TIMEVALUE(E36)<TIME(12,0,0),"Morning","Evening"),D36) -> Morning | S36: Evening Check_Out Median | T36: 0.92916667
A37: EMP019 | B37: 45876 | C37: IT | D37: Morning | E37: 14:05 | F37: 22:22 | G37: Present | H37: =IFERROR(IF(TIMEVALUE(E37)<TIME(12,0,0),"Morning","Evening"),D37) -> Evening
A38: EMP049 | B38: 45762 | C38: Administration | D38: Morning | E38: 14:00 | F38: 22:11 | G38: Present | H38: =IFERROR(IF(TIMEVALUE(E38)<TIME(12,0,0),"Morning","Evening"),D38) -> Evening
A39: EMP061 | B39: 46184 | C39: Sales | D39: Morning | E39: 14:09 | F39: 22:14 | G39: Present | H39: =IFERROR(IF(TIMEVALUE(E39)<TIME(12,0,0),"Morning","Evening"),D39) -> Evening
A40: EMP029 | B40: 45900 | C40: Finance | D40: Morning | E40: 08:09 | F40: 17:01 | G40: Present | H40: =IFERROR(IF(TIMEVALUE(E40)<TIME(12,0,0),"Morning","Evening"),D40) -> Morning
...

Sheet PivotTables
A3: Count of Employee_ID | B3: Column Labels
A4: Row Labels | B4: Absent | C4: Late | D4: Present | E4: Remote | F4: Grand Total
A5: Administration | B5: 2 | C5: 6 | D5: 16 | E5: 6 | F5: 30
A6: Finance | B6: 3 | C6: 9 | D6: 30 | E6: 3 | F6: 45
A7: HR | B7: 1 | C7: 2 | D7: 15 | E7: 2 | F7: 20
A8: IT | B8: 7 | C8: 13 | D8: 49 | E8: 7 | F8: 76
A9: Operations | B9: 2 | C9: 6 | D9: 36 | E9: 7 | F9: 51
A10: Sales | B10: 6 | C10: 9 | D10: 22 | E10: 2 | F10: 39
A11: Grand Total | B11: 21 | C11: 45 | D11: 168 | E11: 27 | F11: 261
A19: Row Labels | B19: Count of Employee_ID
A20: Administration | B20: 30
A21: Finance | B21: 45
A22: HR | B22: 20
A23: IT | B23: 76
A24: Operations | B24: 51
A25: Sales | B25: 39
A26: Grand Total | B26: 261
A39: Count of Employee_ID | B39: Column Labels
A40: Row Labels | B40: Absent | C40: Late | D40: Present | E40: Remote | F40: Grand Total
A41: Evening | B41: 6 | C41: 16 | D41: 58 | E41: 8 | F41: 88
A42: Morning | B42: 15 | C42: 29 | D42: 110 | E42: 19 | F42: 173
A43: Grand Total | B43: 21 | C43: 45 | D43: 168 | E43: 27 | F43: 261
A60: Row Labels | B60: Count of Employee_ID
A61: Absent | B61: 21
A62: Late | B62: 45
A63: Present | B63: 168
A64: Remote | B64: 27
A65: Grand Total | B65: 261

Sheet Dashbaord
E2: EMPLOYEE ATTENDENCE DASHBOARD
D6: Total Records | H6: Present | K6: Late | N6: Absent | Q6: Remote
D7: =COUNTA('cleaned-data'!A2:A262) -> 261 | H7: =COUNTIF('cleaned-data'!G2:G262,"Present") -> 168 | K7: =COUNTIF('cleaned-data'!G2:G262,"Late") -> 45 | N7: =COUNTIF('cleaned-data'!G2:G262,"Absent") -> 21 | Q7: =COUNTIF('cleaned-data'!G2:G262,"Remote") -> 27

Sheet finding
A2: Findings
A4: The dataset originally contained 300 employee attendance records.
A5: 7 duplicate records were identified and removed.
A6: 15 records with missing Employee_ID were removed because the ID is a unique identifier.
A7: 17 records with missing Attendance_Date were removed because the correct date could not be reliably determined.
A8: The final cleaned dataset contains 261 valid records.
A9: IT had the highest number of attendance records among the departments.
A10: Morning shift had more records than the Evening shift.
A11: Some inconsistencies were found in Department, Shift, Check_In, Check_Out, and Attendance_Status and were standardized.
A12: Missing time values in Check_In and Check_Out were handled using median-based imputation, while categorical missing values were handled using the mode or logical rules.
A14: Recommendations
A16: 1. Improve attendance data entry by making Employee_ID and Attendance_Date required fields.
... A19: 4. Validate Shift against Check_In time to detect incorrect shift assignments.
